2025-03-30 17:02:28 - INFO - \u2705 Game environment setup complete!
2025-03-30 17:02:46 - INFO - Planning the game structure...
2025-03-30 17:02:46 - INFO - Iteration 1 of 1 planning iterations
2025-03-30 17:03:14 - INFO - game plan written to game_plan.xml
2025-03-30 17:03:14 - INFO - Game Name: Brick Breaker
2025-03-30 17:03:14 - INFO - ACTIONS: [('Move paddle left', 'LEFT_ARROW'), ('Move paddle right', 'RIGHT_ARROW'), ('Toggle pause', 'P'), ('Exit game', 'ESCAPE')]
2025-03-30 17:03:14 - INFO - ACTIONS: [('Move paddle left', 'LEFT_ARROW'), ('Move paddle right', 'RIGHT_ARROW'), ('Toggle pause', 'P'), ('Exit game', 'ESCAPE')]
2025-03-30 17:03:14 - INFO - Creating game files...
2025-03-30 17:03:17 - INFO - File 'main.py' has been created.
2025-03-30 17:03:20 - INFO - File 'paddle.py' has been created.
2025-03-30 17:03:20 - INFO - File 'ball.py' has been created.
2025-03-30 17:03:21 - INFO - File 'brick.py' has been created.
2025-03-30 17:03:22 - INFO - File 'game.py' has been created.
2025-03-30 17:03:22 - INFO - Game creation complete!
2025-03-30 17:03:22 - INFO - Final game plan:
2025-03-30 17:03:24 - INFO - \u2705 Game process has exited on its own.
2025-03-30 17:03:24 - ERROR - Runtime errors:
Traceback (most recent call last):
  File "<string>", line 1, in <module>
  File "C:\Users\שני אמרגי\OneDrive - Reichman University\מסמכים\software dev using AI\GameGen-Dev\game\main.py", line 15, in main
    game = Game(screen)
           ^^^^^^^^^^^^
TypeError: Game.__init__() takes 1 positional argument but 2 were given

\U0001f6a8 Process exited with return code 1

2025-03-30 17:03:24 - ERROR - Error detected: Runtime errors:
Traceback (most recent call last):
  File "<string>", line 1, in <module>
  File "C:\Users\שני אמרגי\OneDrive - Reichman University\מסמכים\software dev using AI\GameGen-Dev\game\main.py", line 15, in main
    game = Game(screen)
           ^^^^^^^^^^^^
TypeError: Game.__init__() takes 1 positional argument but 2 were given

\U0001f6a8 Process exited with return code 1

2025-03-30 17:03:24 - INFO - Attempt 1 to fix the errors...
2025-03-30 17:03:24 - INFO - Code repair attempting to fix the error...
2025-03-30 17:03:34 - INFO - Updated file: game.py
2025-03-30 17:03:36 - INFO - Running the game after fixing the errors...
2025-03-30 17:03:37 - INFO - \u2705 Game process has exited on its own.
2025-03-30 17:03:37 - ERROR - Runtime errors:
Traceback (most recent call last):
  File "<string>", line 1, in <module>
  File "C:\Users\שני אמרגי\OneDrive - Reichman University\מסמכים\software dev using AI\GameGen-Dev\game\main.py", line 3, in <module>
    from game import Game
  File "C:\Users\שני אמרגי\OneDrive - Reichman University\מסמכים\software dev using AI\GameGen-Dev\game\game.py", line 87
    <file name="main.py">
    ^
SyntaxError: invalid syntax

\U0001f6a8 Process exited with return code 1

2025-03-30 17:03:37 - INFO - Attempt 2 to fix the errors...
2025-03-30 17:03:37 - INFO - Code repair attempting to fix the error...
2025-03-30 17:03:55 - INFO - Updated file: game.py
2025-03-30 17:03:55 - INFO - Updated file: main.py
2025-03-30 17:03:57 - INFO - Running the game after fixing the errors...
2025-03-30 17:03:58 - INFO - \u2705 Game process has exited on its own.
2025-03-30 17:03:58 - ERROR - Runtime errors:
Traceback (most recent call last):
  File "<string>", line 1, in <module>
  File "C:\Users\שני אמרגי\OneDrive - Reichman University\מסמכים\software dev using AI\GameGen-Dev\game\main.py", line 23, in main
    game.update()
  File "C:\Users\שני אמרגי\OneDrive - Reichman University\מסמכים\software dev using AI\GameGen-Dev\game\game.py", line 56, in update
    self.check_collisions()
  File "C:\Users\שני אמרגי\OneDrive - Reichman University\מסמכים\software dev using AI\GameGen-Dev\game\game.py", line 61, in check_collisions
    if brick.check_collision(self.ball.rect):
                             ^^^^^^^^^^^^^^
AttributeError: 'Ball' object has no attribute 'rect'

\U0001f6a8 Process exited with return code 1

2025-03-30 17:03:58 - INFO - Attempt 3 to fix the errors...
2025-03-30 17:03:58 - INFO - Code repair attempting to fix the error...
2025-03-30 17:04:35 - INFO - Updated file: ball.py
2025-03-30 17:04:35 - INFO - Updated file: game.py
2025-03-30 17:04:35 - INFO - Updated file: main.py
2025-03-30 17:04:35 - INFO - Updated file: paddle.py
2025-03-30 17:04:35 - INFO - Updated file: brick.py
2025-03-30 17:04:37 - INFO - Running the game after fixing the errors...
2025-03-30 17:04:47 - ERROR - Runtime errors:
\u26a0\ufe0f Timeout reading process output

2025-03-30 17:04:47 - INFO - Attempt 4 to fix the errors...
2025-03-30 17:04:47 - INFO - Code repair attempting to fix the error...
